<mujoco model="unnamed_model">
  <default>
    <default class="/"/>
  </default>
  <worldbody>
    <geom name="//unnamed_geom_0" class="/" type="plane" size="100 100 0.10000000000000001" pos="0 0 -2"/>
    <body name="body0" pos="0 0 0">
      <joint name="//unnamed_joint_0" class="/" type="free"/>
      <geom name="//unnamed_geom_1" class="/" type="sphere" size="0.5 0.5 0.5"/>
      <body name="body1" pos="0 0 1.061731812010807">
        <geom name="//unnamed_geom_2" class="/" type="sphere" size="0.56173181201080713 0.56173181201080713 0.56173181201080713"/>
        <joint name="//unnamed_joint_1" class="/" type="hinge" axis="0 0 1"/>
        <body name="body2" pos="1.347762117628768 0 0">
          <geom name="//unnamed_geom_3" class="/" type="sphere" size="0.78603030561796083 0.78603030561796083 0.78603030561796083"/>
          <joint name="//unnamed_joint_2" class="/" type="ball" axis="1 0 0"/>
          <body name="body5" pos="0 0 1.5571244917694962">
            <geom name="//unnamed_geom_4" class="/" type="sphere" size="0.77109418615153524 0.77109418615153524 0.77109418615153524"/>
            <joint name="//unnamed_joint_3" class="/" type="hinge" axis="0 0 1"/>
          </body>
        </body>
        <body name="body3" pos="0 0 1.0353317032105207">
          <geom name="//unnamed_geom_5" class="/" type="sphere" size="0.47359989119971346 0.47359989119971346 0.47359989119971346"/>
          <joint name="//unnamed_joint_4" class="/" type="hinge" axis="0 0 1"/>
        </body>
      </body>
    </body>
  </worldbody>
  <actuator>
    <motor name="//unnamed_actuator_0" class="/" ctrllimited="true" ctrlrange="-1 1" joint="//unnamed_joint_1"/>
    <motor name="//unnamed_actuator_1" class="/" ctrllimited="true" ctrlrange="-1 1" joint="//unnamed_joint_2"/>
    <motor name="//unnamed_actuator_2" class="/" ctrllimited="true" ctrlrange="-1 1" joint="//unnamed_joint_3"/>
    <motor name="//unnamed_actuator_3" class="/" ctrllimited="true" ctrlrange="-1 1" joint="//unnamed_joint_4"/>
  </actuator>
</mujoco>
