<mujoco model="unnamed_model">
  <default>
    <default class="/"/>
  </default>
  <worldbody>
    <geom name="//unnamed_geom_0" class="/" type="plane" size="100 100 0.10000000000000001" pos="0 0 -2.0112847517584278"/>
    <body name="body0" pos="0 0 0">
      <joint name="//unnamed_joint_0" class="/" type="free"/>
      <geom name="//unnamed_geom_1" class="/" type="sphere" size="0.5 0.5 0.5"/>
      <body name="body5" pos="0 0 1.4856392766997006">
        <geom name="//unnamed_geom_2" class="/" type="sphere" size="0.98563927669970064 0.98563927669970064 0.98563927669970064"/>
        <joint name="//unnamed_joint_1" class="/" type="hinge" axis="0 0 1"/>
      </body>
      <body name="body1" pos="0 0 -1.0112847517584278">
        <geom name="//unnamed_geom_3" class="/" type="sphere" size="0.5112847517584278 0.5112847517584278 0.5112847517584278"/>
        <joint name="//unnamed_joint_2" class="/" type="hinge" axis="0 0 -1"/>
      </body>
    </body>
  </worldbody>
  <actuator>
    <motor name="//unnamed_actuator_0" class="/" ctrllimited="true" ctrlrange="-1 1" joint="//unnamed_joint_1"/>
    <motor name="//unnamed_actuator_1" class="/" ctrllimited="true" ctrlrange="-1 1" joint="//unnamed_joint_2"/>
  </actuator>
</mujoco>
